2024-10-14 16:45:47,755 INFO    MainThread:34432 [wandb_setup.py:_flush():79] Current SDK version is 0.18.3
2024-10-14 16:45:47,755 INFO    MainThread:34432 [wandb_setup.py:_flush():79] Configure stats pid to 34432
2024-10-14 16:45:47,755 INFO    MainThread:34432 [wandb_setup.py:_flush():79] Loading settings from C:\Users\17724\.config\wandb\settings
2024-10-14 16:45:47,755 INFO    MainThread:34432 [wandb_setup.py:_flush():79] Loading settings from D:\Download\Pytorch-UNet-master\utils\wandb\settings
2024-10-14 16:45:47,755 INFO    MainThread:34432 [wandb_setup.py:_flush():79] Loading settings from environment variables: {}
2024-10-14 16:45:47,755 INFO    MainThread:34432 [wandb_setup.py:_flush():79] Applying setup settings: {'mode': None, '_disable_service': None}
2024-10-14 16:45:47,755 INFO    MainThread:34432 [wandb_setup.py:_flush():79] Inferring run settings from compute environment: {'program_relpath': '..\\train.py', 'program_abspath': 'D:\\Download\\Pytorch-UNet-master\\train.py', 'program': 'D:\\Download\\Pytorch-UNet-master\\train.py'}
2024-10-14 16:45:47,755 INFO    MainThread:34432 [wandb_setup.py:_flush():79] Applying login settings: {'anonymous': 'must'}
2024-10-14 16:45:47,755 INFO    MainThread:34432 [wandb_setup.py:_flush():79] Applying login settings: {'api_key': '***REDACTED***'}
2024-10-14 16:45:47,755 INFO    MainThread:34432 [wandb_init.py:_log_setup():532] Logging user logs to D:\Download\Pytorch-UNet-master\utils\wandb\run-20241014_164547-2gyvqlcc\logs\debug.log
2024-10-14 16:45:47,755 INFO    MainThread:34432 [wandb_init.py:_log_setup():533] Logging internal logs to D:\Download\Pytorch-UNet-master\utils\wandb\run-20241014_164547-2gyvqlcc\logs\debug-internal.log
2024-10-14 16:45:47,755 INFO    MainThread:34432 [wandb_init.py:init():617] calling init triggers
2024-10-14 16:45:47,755 INFO    MainThread:34432 [wandb_init.py:init():624] wandb.init called with sweep_config: {}
config: {}
2024-10-14 16:45:47,755 INFO    MainThread:34432 [wandb_init.py:init():667] starting backend
2024-10-14 16:45:47,755 INFO    MainThread:34432 [wandb_init.py:init():671] sending inform_init request
2024-10-14 16:45:47,758 INFO    MainThread:34432 [backend.py:_multiprocessing_setup():104] multiprocessing start_methods=spawn, using: spawn
2024-10-14 16:45:47,759 INFO    MainThread:34432 [wandb_init.py:init():684] backend started and connected
2024-10-14 16:45:47,761 INFO    MainThread:34432 [wandb_init.py:init():779] updated telemetry
2024-10-14 16:45:47,762 INFO    MainThread:34432 [wandb_init.py:init():812] communicating run to backend with 90.0 second timeout
2024-10-14 16:46:46,147 INFO    Thread-9 (wrapped_target):34432 [retry.py:__call__():172] Retry attempt failed:
Traceback (most recent call last):
  File "F:\env\conda\Lib\site-packages\urllib3\connection.py", line 203, in _new_conn
    sock = connection.create_connection(
           ^^^^^^^^^^^^^^^^^^^^^^^^^^^^^
  File "F:\env\conda\Lib\site-packages\urllib3\util\connection.py", line 85, in create_connection
    raise err
  File "F:\env\conda\Lib\site-packages\urllib3\util\connection.py", line 73, in create_connection
    sock.connect(sa)
TimeoutError: timed out

The above exception was the direct cause of the following exception:

Traceback (most recent call last):
  File "F:\env\conda\Lib\site-packages\urllib3\connectionpool.py", line 791, in urlopen
    response = self._make_request(
               ^^^^^^^^^^^^^^^^^^^
  File "F:\env\conda\Lib\site-packages\urllib3\connectionpool.py", line 492, in _make_request
    raise new_e
  File "F:\env\conda\Lib\site-packages\urllib3\connectionpool.py", line 468, in _make_request
    self._validate_conn(conn)
  File "F:\env\conda\Lib\site-packages\urllib3\connectionpool.py", line 1097, in _validate_conn
    conn.connect()
  File "F:\env\conda\Lib\site-packages\urllib3\connection.py", line 611, in connect
    self.sock = sock = self._new_conn()
                       ^^^^^^^^^^^^^^^^
  File "F:\env\conda\Lib\site-packages\urllib3\connection.py", line 212, in _new_conn
    raise ConnectTimeoutError(
urllib3.exceptions.ConnectTimeoutError: (<urllib3.connection.HTTPSConnection object at 0x00000130C4E5E2D0>, 'Connection to api.wandb.ai timed out. (connect timeout=20)')

The above exception was the direct cause of the following exception:

Traceback (most recent call last):
  File "F:\env\conda\Lib\site-packages\requests\adapters.py", line 486, in send
    resp = conn.urlopen(
           ^^^^^^^^^^^^^
  File "F:\env\conda\Lib\site-packages\urllib3\connectionpool.py", line 845, in urlopen
    retries = retries.increment(
              ^^^^^^^^^^^^^^^^^^
  File "F:\env\conda\Lib\site-packages\urllib3\util\retry.py", line 515, in increment
    raise MaxRetryError(_pool, url, reason) from reason  # type: ignore[arg-type]
    ^^^^^^^^^^^^^^^^^^^^^^^^^^^^^^^^^^^^^^^^^^^^^^^^^^^
urllib3.exceptions.MaxRetryError: HTTPSConnectionPool(host='api.wandb.ai', port=443): Max retries exceeded with url: /graphql (Caused by ConnectTimeoutError(<urllib3.connection.HTTPSConnection object at 0x00000130C4E5E2D0>, 'Connection to api.wandb.ai timed out. (connect timeout=20)'))

During handling of the above exception, another exception occurred:

Traceback (most recent call last):
  File "F:\env\conda\Lib\site-packages\wandb\sdk\lib\retry.py", line 131, in __call__
    result = self._call_fn(*args, **kwargs)
             ^^^^^^^^^^^^^^^^^^^^^^^^^^^^^^
  File "F:\env\conda\Lib\site-packages\wandb\sdk\internal\internal_api.py", line 347, in execute
    return self.client.execute(*args, **kwargs)  # type: ignore
           ^^^^^^^^^^^^^^^^^^^^^^^^^^^^^^^^^^^^
  File "F:\env\conda\Lib\site-packages\wandb\vendor\gql-0.2.0\wandb_gql\client.py", line 52, in execute
    result = self._get_result(document, *args, **kwargs)
             ^^^^^^^^^^^^^^^^^^^^^^^^^^^^^^^^^^^^^^^^^^^
  File "F:\env\conda\Lib\site-packages\wandb\vendor\gql-0.2.0\wandb_gql\client.py", line 60, in _get_result
    return self.transport.execute(document, *args, **kwargs)
           ^^^^^^^^^^^^^^^^^^^^^^^^^^^^^^^^^^^^^^^^^^^^^^^^^
  File "F:\env\conda\Lib\site-packages\wandb\sdk\lib\gql_request.py", line 58, in execute
    request = self.session.post(self.url, **post_args)
              ^^^^^^^^^^^^^^^^^^^^^^^^^^^^^^^^^^^^^^^^
  File "F:\env\conda\Lib\site-packages\requests\sessions.py", line 637, in post
    return self.request("POST", url, data=data, json=json, **kwargs)
           ^^^^^^^^^^^^^^^^^^^^^^^^^^^^^^^^^^^^^^^^^^^^^^^^^^^^^^^^^
  File "F:\env\conda\Lib\site-packages\requests\sessions.py", line 589, in request
    resp = self.send(prep, **send_kwargs)
           ^^^^^^^^^^^^^^^^^^^^^^^^^^^^^^
  File "F:\env\conda\Lib\site-packages\requests\sessions.py", line 703, in send
    r = adapter.send(request, **kwargs)
        ^^^^^^^^^^^^^^^^^^^^^^^^^^^^^^^
  File "F:\env\conda\Lib\site-packages\requests\adapters.py", line 507, in send
    raise ConnectTimeout(e, request=request)
requests.exceptions.ConnectTimeout: HTTPSConnectionPool(host='api.wandb.ai', port=443): Max retries exceeded with url: /graphql (Caused by ConnectTimeoutError(<urllib3.connection.HTTPSConnection object at 0x00000130C4E5E2D0>, 'Connection to api.wandb.ai timed out. (connect timeout=20)'))
2024-10-14 16:47:18,551 ERROR   MainThread:34432 [wandb_init.py:init():838] encountered error: Run initialization has timed out after 90.0 sec. 
Please refer to the documentation for additional information: https://docs.wandb.ai/guides/track/tracking-faq#initstarterror-error-communicating-with-wandb-process-
2024-10-14 16:47:18,551 ERROR   MainThread:34432 [wandb_init.py:init():1262] error in wandb.init()
Traceback (most recent call last):
  File "F:\env\conda\Lib\site-packages\wandb\sdk\wandb_init.py", line 1252, in init
    return wi.init()
           ^^^^^^^^^
  File "F:\env\conda\Lib\site-packages\wandb\sdk\wandb_init.py", line 844, in init
    raise error
wandb.errors.errors.CommError: Run initialization has timed out after 90.0 sec. 
Please refer to the documentation for additional information: https://docs.wandb.ai/guides/track/tracking-faq#initstarterror-error-communicating-with-wandb-process-
2024-10-14 16:47:20,595 WARNING MsgRouterThr:34432 [router.py:message_loop():77] message_loop has been closed
